Watching for file changes with StatReloader
C:\Users\Myuse\OneDrive\Dokumente\vscode-projects\w3 schools html\mysite\additem\views.py changed, reloading.
Watching for file changes with StatReloader
C:\Users\Myuse\OneDrive\Dokumente\vscode-projects\w3 schools html\mysite\mysite\settings.py changed, reloading.
Watching for file changes with StatReloader
C:\Users\Myuse\OneDrive\Dokumente\vscode-projects\w3 schools html\mysite\additem\views.py changed, reloading.
Watching for file changes with StatReloader
C:\Users\Myuse\OneDrive\Dokumente\vscode-projects\w3 schools html\mysite\additem\views.py changed, reloading.
Watching for file changes with StatReloader
C:\Users\Myuse\OneDrive\Dokumente\vscode-projects\w3 schools html\mysite\additem\views.py changed, reloading.
Watching for file changes with StatReloader
C:\Users\Myuse\OneDrive\Dokumente\vscode-projects\w3 schools html\mysite\additem\views.py changed, reloading.
Watching for file changes with StatReloader
GET request received
C:\Users\Myuse\OneDrive\Dokumente\vscode-projects\w3 schools html\mysite\mysite\settings.py changed, reloading.
Watching for file changes with StatReloader
GET request received
C:\Users\Myuse\OneDrive\Dokumente\vscode-projects\w3 schools html\mysite\additem\views.py changed, reloading.
Watching for file changes with StatReloader
C:\Users\Myuse\OneDrive\Dokumente\vscode-projects\w3 schools html\mysite\additem\views.py changed, reloading.
Watching for file changes with StatReloader
C:\Users\Myuse\OneDrive\Dokumente\vscode-projects\w3 schools html\mysite\additem\views.py changed, reloading.
Watching for file changes with StatReloader
C:\Users\Myuse\OneDrive\Dokumente\vscode-projects\w3 schools html\mysite\additem\views.py changed, reloading.
Watching for file changes with StatReloader
C:\Users\Myuse\OneDrive\Dokumente\vscode-projects\w3 schools html\mysite\additem\views.py changed, reloading.
Watching for file changes with StatReloader
C:\Users\Myuse\OneDrive\Dokumente\vscode-projects\w3 schools html\mysite\additem\views.py changed, reloading.
Watching for file changes with StatReloader
C:\Users\Myuse\OneDrive\Dokumente\vscode-projects\w3 schools html\mysite\additem\views.py changed, reloading.
Watching for file changes with StatReloader
Whatever to log
GET request received
Whatever to log
GET request received
C:\Users\Myuse\OneDrive\Dokumente\vscode-projects\w3 schools html\mysite\additem\views.py changed, reloading.
Watching for file changes with StatReloader
Whatever to log
GET request received
Whatever to log
GET request received
C:\Users\Myuse\OneDrive\Dokumente\vscode-projects\w3 schools html\mysite\additem\views.py changed, reloading.
Watching for file changes with StatReloader
Whatever to log
GET request received
Whatever to log
GET request received
C:\Users\Myuse\OneDrive\Dokumente\vscode-projects\w3 schools html\mysite\additem\views.py changed, reloading.
Watching for file changes with StatReloader
Not Found: /hompegae
C:\Users\Myuse\OneDrive\Dokumente\vscode-projects\w3 schools html\mysite\additem\views.py changed, reloading.
Watching for file changes with StatReloader
GET request received
C:\Users\Myuse\OneDrive\Dokumente\vscode-projects\w3 schools html\mysite\additem\views.py changed, reloading.
Watching for file changes with StatReloader
GET request received
C:\Users\Myuse\OneDrive\Dokumente\vscode-projects\w3 schools html\mysite\additem\views.py changed, reloading.
Watching for file changes with StatReloader
Whatever to log
Whatever to log
Whatever to log
Whatever to log
Watching for file changes with StatReloader
Not Found: /
Not Found: /favicon.ico
test
test
C:\Users\Myuse\OneDrive\Dokumente\vscode-projects\w3 schools html\mysite\additem\views.py changed, reloading.
Watching for file changes with StatReloader
test
test
Watching for file changes with StatReloader
Not Found: /
Not Found: /favicon.ico
test
C:\Users\Myuse\OneDrive\Dokumente\vscode-projects\w3 schools html\mysite\additem\views.py changed, reloading.
Watching for file changes with StatReloader
Watching for file changes with StatReloader
C:\Users\Myuse\OneDrive\Dokumente\vscode-projects\w3 schools html\mysite\additem\forms.py changed, reloading.
Watching for file changes with StatReloader
Watching for file changes with StatReloader
C:\Users\Myuse\OneDrive\Dokumente\vscode-projects\w3 schools html\mysite\additem\views.py changed, reloading.
Watching for file changes with StatReloader
Not Found: /
Not Found: /favicon.ico
test
test
test
test
C:\Users\Myuse\OneDrive\Dokumente\vscode-projects\w3 schools html\mysite\additem\views.py changed, reloading.
Watching for file changes with StatReloader
test
test
test
test
test
C:\Users\Myuse\OneDrive\Dokumente\vscode-projects\w3 schools html\mysite\additem\views.py changed, reloading.
Watching for file changes with StatReloader
C:\Users\Myuse\OneDrive\Dokumente\vscode-projects\w3 schools html\mysite\additem\urls.py changed, reloading.
Watching for file changes with StatReloader
C:\Users\Myuse\OneDrive\Dokumente\vscode-projects\w3 schools html\mysite\additem\urls.py changed, reloading.
Watching for file changes with StatReloader
C:\Users\Myuse\OneDrive\Dokumente\vscode-projects\w3 schools html\mysite\additem\urls.py changed, reloading.
Watching for file changes with StatReloader
C:\Users\Myuse\OneDrive\Dokumente\vscode-projects\w3 schools html\mysite\additem\urls.py changed, reloading.
Watching for file changes with StatReloader
C:\Users\Myuse\OneDrive\Dokumente\vscode-projects\w3 schools html\mysite\additem\urls.py changed, reloading.
Watching for file changes with StatReloader
C:\Users\Myuse\OneDrive\Dokumente\vscode-projects\w3 schools html\mysite\additem\urls.py changed, reloading.
Watching for file changes with StatReloader
C:\Users\Myuse\OneDrive\Dokumente\vscode-projects\w3 schools html\mysite\additem\views.py changed, reloading.
Watching for file changes with StatReloader
C:\Users\Myuse\OneDrive\Dokumente\vscode-projects\w3 schools html\mysite\additem\views.py changed, reloading.
Watching for file changes with StatReloader
Watching for file changes with StatReloader
Not Found: /
Not Found: /favicon.ico
Not Found: /
test
test
test
test
Internal Server Error: /additem/
Traceback (most recent call last):
  File "C:\Users\Myuse\AppData\Local\Programs\Python\Python311\Lib\site-packages\django\core\handlers\exception.py", line 55, in inner
    response = get_response(request)
               ^^^^^^^^^^^^^^^^^^^^^
  File "C:\Users\Myuse\AppData\Local\Programs\Python\Python311\Lib\site-packages\django\core\handlers\base.py", line 197, in _get_response
    response = wrapped_callback(request, *callback_args, **callback_kwargs)
               ^^^^^^^^^^^^^^^^^^^^^^^^^^^^^^^^^^^^^^^^^^^^^^^^^^^^^^^^^^^^
  File "C:\Users\Myuse\OneDrive\Dokumente\vscode-projects\w3 schools html\mysite\additem\views.py", line 20, in additem
    return HttpResponse(template.render())
                       ^^^^^^^^^^^^^^^^^
  File "C:\Users\Myuse\AppData\Local\Programs\Python\Python311\Lib\site-packages\django\template\backends\django.py", line 61, in render
    return self.template.render(context)
           ^^^^^^^^^^^^^^^^^^^^^^^^^^^^^
  File "C:\Users\Myuse\AppData\Local\Programs\Python\Python311\Lib\site-packages\django\template\base.py", line 175, in render
    return self._render(context)
           ^^^^^^^^^^^^^^^^^^^^^
  File "C:\Users\Myuse\AppData\Local\Programs\Python\Python311\Lib\site-packages\django\template\base.py", line 167, in _render
    return self.nodelist.render(context)
           ^^^^^^^^^^^^^^^^^^^^^^^^^^^^^
  File "C:\Users\Myuse\AppData\Local\Programs\Python\Python311\Lib\site-packages\django\template\base.py", line 1005, in render
    return SafeString("".join([node.render_annotated(context) for node in self]))
                              ^^^^^^^^^^^^^^^^^^^^^^^^^^^^^^^^^^^^^^^^^^^^^^^^^
  File "C:\Users\Myuse\AppData\Local\Programs\Python\Python311\Lib\site-packages\django\template\base.py", line 1005, in <listcomp>
    return SafeString("".join([node.render_annotated(context) for node in self]))
                               ^^^^^^^^^^^^^^^^^^^^^^^^^^^^^^
  File "C:\Users\Myuse\AppData\Local\Programs\Python\Python311\Lib\site-packages\django\template\base.py", line 966, in render_annotated
    return self.render(context)
           ^^^^^^^^^^^^^^^^^^^^
  File "C:\Users\Myuse\AppData\Local\Programs\Python\Python311\Lib\site-packages\django\template\defaulttags.py", line 471, in render
    url = reverse(view_name, args=args, kwargs=kwargs, current_app=current_app)
          ^^^^^^^^^^^^^^^^^^^^^^^^^^^^^^^^^^^^^^^^^^^^^^^^^^^^^^^^^^^^^^^^^^^^^
  File "C:\Users\Myuse\AppData\Local\Programs\Python\Python311\Lib\site-packages\django\urls\base.py", line 88, in reverse
    return resolver._reverse_with_prefix(view, prefix, *args, **kwargs)
           ^^^^^^^^^^^^^^^^^^^^^^^^^^^^^^^^^^^^^^^^^^^^^^^^^^^^^^^^^^^^
  File "C:\Users\Myuse\AppData\Local\Programs\Python\Python311\Lib\site-packages\django\urls\resolvers.py", line 828, in _reverse_with_prefix
    raise NoReverseMatch(msg)
django.urls.exceptions.NoReverseMatch: Reverse for 'update-db' not found. 'update-db' is not a valid view function or pattern name.
Watching for file changes with StatReloader
test
test2
test2
C:\Users\Myuse\OneDrive\Dokumente\vscode-projects\w3 schools html\mysite\additem\views.py changed, reloading.
Watching for file changes with StatReloader
test
test2
test2
test
test2
test2
C:\Users\Myuse\OneDrive\Dokumente\vscode-projects\w3 schools html\mysite\additem\forms.py changed, reloading.
Watching for file changes with StatReloader
C:\Users\Myuse\OneDrive\Dokumente\vscode-projects\w3 schools html\mysite\additem\views.py changed, reloading.
Watching for file changes with StatReloader
test
test2
test2
<tr>
    <th><label for="id_item_name">item name:</label></th>
    <td>
      <ul class="errorlist"><li>This field is required.</li></ul>
      <input type="text" name="item_name" maxlength="100" required id="id_item_name">
      
      
    </td>
  </tr>

  <tr>
    <th><label for="id_link">link:</label></th>
    <td>
      
      <input type="text" name="link" value="ff" maxlength="50" required id="id_link">
      
      
    </td>
  </tr>

  <tr>
    <th><label for="id_price">price:</label></th>
    <td>
      
      <input type="number" name="price" value="11" step="0.01" required id="id_price">
      
      
        
      
    </td>
  </tr>
test
C:\Users\Myuse\OneDrive\Dokumente\vscode-projects\w3 schools html\mysite\additem\forms.py changed, reloading.
Watching for file changes with StatReloader
C:\Users\Myuse\OneDrive\Dokumente\vscode-projects\w3 schools html\mysite\additem\views.py changed, reloading.
Watching for file changes with StatReloader
test2
test2
<tr>
    <th><label for="id_item_name">item_name:</label></th>
    <td>
      <ul class="errorlist"><li>This field is required.</li></ul>
      <input type="text" name="item_name" maxlength="100" required id="id_item_name">
      
      
    </td>
  </tr>

  <tr>
    <th><label for="id_link">link:</label></th>
    <td>
      
      <input type="text" name="link" value="ff" maxlength="50" required id="id_link">
      
      
    </td>
  </tr>

  <tr>
    <th><label for="id_price">price:</label></th>
    <td>
      
      <input type="number" name="price" value="33" step="0.01" required id="id_price">
      
      
        
      
    </td>
  </tr>
C:\Users\Myuse\OneDrive\Dokumente\vscode-projects\w3 schools html\mysite\additem\models.py changed, reloading.
Watching for file changes with StatReloader
test
test2
test2
<tr>
    <th><label for="id_item_name">item_name:</label></th>
    <td>
      
      <input type="text" name="item_name" value="dd" maxlength="100" required id="id_item_name">
      
      
    </td>
  </tr>

  <tr>
    <th><label for="id_link">link:</label></th>
    <td>
      
      <input type="text" name="link" value="ff" maxlength="50" required id="id_link">
      
      
    </td>
  </tr>

  <tr>
    <th><label for="id_price">price:</label></th>
    <td>
      
      <input type="number" name="price" value="33" step="0.01" required id="id_price">
      
      
        
      
    </td>
  </tr>
test3
Internal Server Error: /update-db/
Traceback (most recent call last):
  File "C:\Users\Myuse\AppData\Local\Programs\Python\Python311\Lib\site-packages\django\core\handlers\exception.py", line 55, in inner
    response = get_response(request)
               ^^^^^^^^^^^^^^^^^^^^^
  File "C:\Users\Myuse\AppData\Local\Programs\Python\Python311\Lib\site-packages\django\core\handlers\base.py", line 197, in _get_response
    response = wrapped_callback(request, *callback_args, **callback_kwargs)
               ^^^^^^^^^^^^^^^^^^^^^^^^^^^^^^^^^^^^^^^^^^^^^^^^^^^^^^^^^^^^
  File "C:\Users\Myuse\OneDrive\Dokumente\vscode-projects\w3 schools html\mysite\additem\views.py", line 37, in update_db
    Member.objects.create(titel=titel, link=link, price=price)
  File "C:\Users\Myuse\AppData\Local\Programs\Python\Python311\Lib\site-packages\django\db\models\manager.py", line 87, in manager_method
    return getattr(self.get_queryset(), name)(*args, **kwargs)
           ^^^^^^^^^^^^^^^^^^^^^^^^^^^^^^^^^^^^^^^^^^^^^^^^^^^
  File "C:\Users\Myuse\AppData\Local\Programs\Python\Python311\Lib\site-packages\django\db\models\query.py", line 656, in create
    obj = self.model(**kwargs)
          ^^^^^^^^^^^^^^^^^^^^
  File "C:\Users\Myuse\AppData\Local\Programs\Python\Python311\Lib\site-packages\django\db\models\base.py", line 567, in __init__
    raise TypeError(
TypeError: Member() got unexpected keyword arguments: 'titel'
C:\Users\Myuse\OneDrive\Dokumente\vscode-projects\w3 schools html\mysite\additem\views.py changed, reloading.
Watching for file changes with StatReloader
test
test2
test2
<tr>
    <th><label for="id_item_name">item_name:</label></th>
    <td>
      
      <input type="text" name="item_name" value="dd" maxlength="100" required id="id_item_name">
      
      
    </td>
  </tr>

  <tr>
    <th><label for="id_link">link:</label></th>
    <td>
      
      <input type="text" name="link" value="ff" maxlength="50" required id="id_link">
      
      
    </td>
  </tr>

  <tr>
    <th><label for="id_price">price:</label></th>
    <td>
      
      <input type="number" name="price" value="33" step="0.01" required id="id_price">
      
      
        
      
    </td>
  </tr>
test3
Internal Server Error: /update-db/
Traceback (most recent call last):
  File "C:\Users\Myuse\AppData\Local\Programs\Python\Python311\Lib\site-packages\django\db\backends\utils.py", line 89, in _execute
    return self.cursor.execute(sql, params)
           ^^^^^^^^^^^^^^^^^^^^^^^^^^^^^^^^
  File "C:\Users\Myuse\AppData\Local\Programs\Python\Python311\Lib\site-packages\django\db\backends\sqlite3\base.py", line 328, in execute
    return super().execute(query, params)
           ^^^^^^^^^^^^^^^^^^^^^^^^^^^^^^
sqlite3.OperationalError: table additem_member has no column named item_name

The above exception was the direct cause of the following exception:

Traceback (most recent call last):
  File "C:\Users\Myuse\AppData\Local\Programs\Python\Python311\Lib\site-packages\django\core\handlers\exception.py", line 55, in inner
    response = get_response(request)
               ^^^^^^^^^^^^^^^^^^^^^
  File "C:\Users\Myuse\AppData\Local\Programs\Python\Python311\Lib\site-packages\django\core\handlers\base.py", line 197, in _get_response
    response = wrapped_callback(request, *callback_args, **callback_kwargs)
               ^^^^^^^^^^^^^^^^^^^^^^^^^^^^^^^^^^^^^^^^^^^^^^^^^^^^^^^^^^^^
  File "C:\Users\Myuse\OneDrive\Dokumente\vscode-projects\w3 schools html\mysite\additem\views.py", line 37, in update_db
    Member.objects.create(item_name=item_name, link=link, price=price)
  File "C:\Users\Myuse\AppData\Local\Programs\Python\Python311\Lib\site-packages\django\db\models\manager.py", line 87, in manager_method
    return getattr(self.get_queryset(), name)(*args, **kwargs)
           ^^^^^^^^^^^^^^^^^^^^^^^^^^^^^^^^^^^^^^^^^^^^^^^^^^^
  File "C:\Users\Myuse\AppData\Local\Programs\Python\Python311\Lib\site-packages\django\db\models\query.py", line 658, in create
    obj.save(force_insert=True, using=self.db)
  File "C:\Users\Myuse\AppData\Local\Programs\Python\Python311\Lib\site-packages\django\db\models\base.py", line 814, in save
    self.save_base(
  File "C:\Users\Myuse\AppData\Local\Programs\Python\Python311\Lib\site-packages\django\db\models\base.py", line 877, in save_base
    updated = self._save_table(
              ^^^^^^^^^^^^^^^^^
  File "C:\Users\Myuse\AppData\Local\Programs\Python\Python311\Lib\site-packages\django\db\models\base.py", line 1020, in _save_table
    results = self._do_insert(
              ^^^^^^^^^^^^^^^^
  File "C:\Users\Myuse\AppData\Local\Programs\Python\Python311\Lib\site-packages\django\db\models\base.py", line 1061, in _do_insert
    return manager._insert(
           ^^^^^^^^^^^^^^^^
  File "C:\Users\Myuse\AppData\Local\Programs\Python\Python311\Lib\site-packages\django\db\models\manager.py", line 87, in manager_method
    return getattr(self.get_queryset(), name)(*args, **kwargs)
           ^^^^^^^^^^^^^^^^^^^^^^^^^^^^^^^^^^^^^^^^^^^^^^^^^^^
  File "C:\Users\Myuse\AppData\Local\Programs\Python\Python311\Lib\site-packages\django\db\models\query.py", line 1805, in _insert
    return query.get_compiler(using=using).execute_sql(returning_fields)
           ^^^^^^^^^^^^^^^^^^^^^^^^^^^^^^^^^^^^^^^^^^^^^^^^^^^^^^^^^^^^^
  File "C:\Users\Myuse\AppData\Local\Programs\Python\Python311\Lib\site-packages\django\db\models\sql\compiler.py", line 1822, in execute_sql
    cursor.execute(sql, params)
  File "C:\Users\Myuse\AppData\Local\Programs\Python\Python311\Lib\site-packages\django\db\backends\utils.py", line 102, in execute
    return super().execute(sql, params)
           ^^^^^^^^^^^^^^^^^^^^^^^^^^^^
  File "C:\Users\Myuse\AppData\Local\Programs\Python\Python311\Lib\site-packages\django\db\backends\utils.py", line 67, in execute
    return self._execute_with_wrappers(
           ^^^^^^^^^^^^^^^^^^^^^^^^^^^^
  File "C:\Users\Myuse\AppData\Local\Programs\Python\Python311\Lib\site-packages\django\db\backends\utils.py", line 80, in _execute_with_wrappers
    return executor(sql, params, many, context)
           ^^^^^^^^^^^^^^^^^^^^^^^^^^^^^^^^^^^^
  File "C:\Users\Myuse\AppData\Local\Programs\Python\Python311\Lib\site-packages\django\db\backends\utils.py", line 84, in _execute
    with self.db.wrap_database_errors:
  File "C:\Users\Myuse\AppData\Local\Programs\Python\Python311\Lib\site-packages\django\db\utils.py", line 91, in __exit__
    raise dj_exc_value.with_traceback(traceback) from exc_value
  File "C:\Users\Myuse\AppData\Local\Programs\Python\Python311\Lib\site-packages\django\db\backends\utils.py", line 89, in _execute
    return self.cursor.execute(sql, params)
           ^^^^^^^^^^^^^^^^^^^^^^^^^^^^^^^^
  File "C:\Users\Myuse\AppData\Local\Programs\Python\Python311\Lib\site-packages\django\db\backends\sqlite3\base.py", line 328, in execute
    return super().execute(query, params)
           ^^^^^^^^^^^^^^^^^^^^^^^^^^^^^^
django.db.utils.OperationalError: table additem_member has no column named item_name
C:\Users\Myuse\OneDrive\Dokumente\vscode-projects\w3 schools html\mysite\additem\models.py changed, reloading.
Watching for file changes with StatReloader
test
test2
test2
<tr>
    <th><label for="id_item_name">item_name:</label></th>
    <td>
      
      <input type="text" name="item_name" value="dd" maxlength="100" required id="id_item_name">
      
      
    </td>
  </tr>

  <tr>
    <th><label for="id_link">link:</label></th>
    <td>
      
      <input type="text" name="link" value="ff" maxlength="50" required id="id_link">
      
      
    </td>
  </tr>

  <tr>
    <th><label for="id_price">price:</label></th>
    <td>
      
      <input type="number" name="price" value="33" step="0.01" required id="id_price">
      
      
        
      
    </td>
  </tr>
test3
Internal Server Error: /update-db/
Traceback (most recent call last):
  File "C:\Users\Myuse\AppData\Local\Programs\Python\Python311\Lib\site-packages\django\db\backends\utils.py", line 89, in _execute
    return self.cursor.execute(sql, params)
           ^^^^^^^^^^^^^^^^^^^^^^^^^^^^^^^^
  File "C:\Users\Myuse\AppData\Local\Programs\Python\Python311\Lib\site-packages\django\db\backends\sqlite3\base.py", line 328, in execute
    return super().execute(query, params)
           ^^^^^^^^^^^^^^^^^^^^^^^^^^^^^^
sqlite3.OperationalError: table additem_member has no column named item_name

The above exception was the direct cause of the following exception:

Traceback (most recent call last):
  File "C:\Users\Myuse\AppData\Local\Programs\Python\Python311\Lib\site-packages\django\core\handlers\exception.py", line 55, in inner
    response = get_response(request)
               ^^^^^^^^^^^^^^^^^^^^^
  File "C:\Users\Myuse\AppData\Local\Programs\Python\Python311\Lib\site-packages\django\core\handlers\base.py", line 197, in _get_response
    response = wrapped_callback(request, *callback_args, **callback_kwargs)
               ^^^^^^^^^^^^^^^^^^^^^^^^^^^^^^^^^^^^^^^^^^^^^^^^^^^^^^^^^^^^
  File "C:\Users\Myuse\OneDrive\Dokumente\vscode-projects\w3 schools html\mysite\additem\views.py", line 37, in update_db
    Member.objects.create(item_name=item_name, link=link, price=price)
  File "C:\Users\Myuse\AppData\Local\Programs\Python\Python311\Lib\site-packages\django\db\models\manager.py", line 87, in manager_method
    return getattr(self.get_queryset(), name)(*args, **kwargs)
           ^^^^^^^^^^^^^^^^^^^^^^^^^^^^^^^^^^^^^^^^^^^^^^^^^^^
  File "C:\Users\Myuse\AppData\Local\Programs\Python\Python311\Lib\site-packages\django\db\models\query.py", line 658, in create
    obj.save(force_insert=True, using=self.db)
  File "C:\Users\Myuse\AppData\Local\Programs\Python\Python311\Lib\site-packages\django\db\models\base.py", line 814, in save
    self.save_base(
  File "C:\Users\Myuse\AppData\Local\Programs\Python\Python311\Lib\site-packages\django\db\models\base.py", line 877, in save_base
    updated = self._save_table(
              ^^^^^^^^^^^^^^^^^
  File "C:\Users\Myuse\AppData\Local\Programs\Python\Python311\Lib\site-packages\django\db\models\base.py", line 1020, in _save_table
    results = self._do_insert(
              ^^^^^^^^^^^^^^^^
  File "C:\Users\Myuse\AppData\Local\Programs\Python\Python311\Lib\site-packages\django\db\models\base.py", line 1061, in _do_insert
    return manager._insert(
           ^^^^^^^^^^^^^^^^
  File "C:\Users\Myuse\AppData\Local\Programs\Python\Python311\Lib\site-packages\django\db\models\manager.py", line 87, in manager_method
    return getattr(self.get_queryset(), name)(*args, **kwargs)
           ^^^^^^^^^^^^^^^^^^^^^^^^^^^^^^^^^^^^^^^^^^^^^^^^^^^
  File "C:\Users\Myuse\AppData\Local\Programs\Python\Python311\Lib\site-packages\django\db\models\query.py", line 1805, in _insert
    return query.get_compiler(using=using).execute_sql(returning_fields)
           ^^^^^^^^^^^^^^^^^^^^^^^^^^^^^^^^^^^^^^^^^^^^^^^^^^^^^^^^^^^^^
  File "C:\Users\Myuse\AppData\Local\Programs\Python\Python311\Lib\site-packages\django\db\models\sql\compiler.py", line 1822, in execute_sql
    cursor.execute(sql, params)
  File "C:\Users\Myuse\AppData\Local\Programs\Python\Python311\Lib\site-packages\django\db\backends\utils.py", line 102, in execute
    return super().execute(sql, params)
           ^^^^^^^^^^^^^^^^^^^^^^^^^^^^
  File "C:\Users\Myuse\AppData\Local\Programs\Python\Python311\Lib\site-packages\django\db\backends\utils.py", line 67, in execute
    return self._execute_with_wrappers(
           ^^^^^^^^^^^^^^^^^^^^^^^^^^^^
  File "C:\Users\Myuse\AppData\Local\Programs\Python\Python311\Lib\site-packages\django\db\backends\utils.py", line 80, in _execute_with_wrappers
    return executor(sql, params, many, context)
           ^^^^^^^^^^^^^^^^^^^^^^^^^^^^^^^^^^^^
  File "C:\Users\Myuse\AppData\Local\Programs\Python\Python311\Lib\site-packages\django\db\backends\utils.py", line 84, in _execute
    with self.db.wrap_database_errors:
  File "C:\Users\Myuse\AppData\Local\Programs\Python\Python311\Lib\site-packages\django\db\utils.py", line 91, in __exit__
    raise dj_exc_value.with_traceback(traceback) from exc_value
  File "C:\Users\Myuse\AppData\Local\Programs\Python\Python311\Lib\site-packages\django\db\backends\utils.py", line 89, in _execute
    return self.cursor.execute(sql, params)
           ^^^^^^^^^^^^^^^^^^^^^^^^^^^^^^^^
  File "C:\Users\Myuse\AppData\Local\Programs\Python\Python311\Lib\site-packages\django\db\backends\sqlite3\base.py", line 328, in execute
    return super().execute(query, params)
           ^^^^^^^^^^^^^^^^^^^^^^^^^^^^^^
django.db.utils.OperationalError: table additem_member has no column named item_name
